<mujoco model="ur3">
  <compiler angle="radian" meshdir="../ur_description/meshes"/>
  <asset>
    <mesh name="base" file="base.stl"/>
    <mesh name="shoulder" file="shoulder.stl"/>
    <mesh name="upperarm" file="upperarm.stl"/>
    <mesh name="forearm" file="forearm.stl"/>
    <mesh name="wrist1" file="wrist1.stl"/>
    <mesh name="wrist2" file="wrist2.stl"/>
    <mesh name="wrist3" file="wrist3.stl"/>
  </asset>
  <worldbody>
    <body name="base_link">
      <inertial pos="0.000000000 0.000000000 0.000000000" quat="0.5 0.5 -0.5 0.5" mass="2.69" diaginertia="0.006118063 0.003546233 0.003475795"/>
      <geom type="mesh" contype="0" conaffinity="0" group="1" density="0" rgba="0.7 0.7 0.7 1" mesh="base"/>
      <geom type="mesh" rgba="0.7 0.7 0.7 1" mesh="base"/>
      <body name="shoulder_link" pos="0 0 0.1519">
        <inertial pos="0.000000000 0.000000000 0.000000000" mass="2.69" diaginertia="0.008586223 0.008515785 0.006118063"/>
        <joint name="shoulder_pan_joint" pos="0 0 0" axis="0 0 1" range="-6.28319 6.28319" actuatorfrcrange="-330 330" armature="0.000038200"/>
        <geom type="mesh" contype="0" conaffinity="0" group="1" density="0" rgba="0.7 0.7 0.7 1" mesh="shoulder"/>
        <geom type="mesh" rgba="0.7 0.7 0.7 1" mesh="shoulder"/>
        <body name="upper_arm_link" pos="0 0.1198 0" quat="0.707107 0 0.707107 0">
          <inertial pos="0.000000000 0.000000000 0.142277372" mass="4.109999999999999" diaginertia="0.030742870 0.030672432 0.010111813"/>
          <joint name="shoulder_lift_joint" pos="0 0 0" axis="0 1 0" range="-6.28319 6.28319" actuatorfrcrange="-330 330" armature="0.000038200"/>
          <geom type="mesh" contype="0" conaffinity="0" group="1" density="0" rgba="0.7 0.7 0.7 1" mesh="upperarm"/>
          <geom type="mesh" rgba="0.7 0.7 0.7 1" mesh="upperarm"/>
          <body name="forearm_link" pos="0 -0.0925 0.24365">
            <inertial pos="0.000000000 0.000000000 0.144353846" mass="1.95" diaginertia="0.012108649 0.012038211 0.004036813"/>
            <joint name="elbow_joint" pos="0 0 0" axis="0 1 0" range="-3.14159 3.14159" actuatorfrcrange="-150 150" armature="0.000038200"/>
            <geom type="mesh" contype="0" conaffinity="0" group="1" density="0" rgba="0.7 0.7 0.7 1" mesh="forearm"/>
            <geom type="mesh" rgba="0.7 0.7 0.7 1" mesh="forearm"/>
            <body name="wrist_1_link" pos="0 0 0.21325" quat="0.707107 0 0.707107 0">
              <inertial pos="0.000000000 0.039385570 0.000000000" quat="0.5 0.5 -0.5 0.5" mass="1.49" diaginertia="0.005422857 0.002578063 0.005187419"/>
              <joint name="wrist_1_joint" pos="0 0 0" axis="0 1 0" range="-6.28319 6.28319" actuatorfrcrange="-54 54" armature="0.000038200"/>
              <geom type="mesh" contype="0" conaffinity="0" group="1" density="0" rgba="0.7 0.7 0.7 1" mesh="wrist1"/>
              <geom type="mesh" rgba="0.7 0.7 0.7 1" mesh="wrist1"/>
              <body name="wrist_2_link" pos="0 0.08505 0">
                <inertial pos="0.000000000 0.000000000 0.039524497" quat="0.5 0.5 -0.5 0.5" mass="1.49" diaginertia="0.005441795 0.005206358 0.002578063"/>
                <joint name="wrist_2_joint" pos="0 0 0" axis="0 0 1" range="-6.28319 6.28319" actuatorfrcrange="-54 54" armature="0.000038200"/>
                <geom type="mesh" contype="0" conaffinity="0" group="1" density="0" rgba="0.7 0.7 0.7 1" mesh="wrist2"/>
                <geom type="mesh" rgba="0.7 0.7 0.7 1" mesh="wrist2"/>
                <body name="wrist_3_link" pos="0 0 0.08535">
                  <inertial pos="0 0 0" quat="0.5 0.5 -0.5 0.5" mass="0.35" diaginertia="0.000984375 0.000912187 0.000912187"/>
                  <joint name="wrist_3_joint" pos="0 0 0" axis="0 1 0" range="-6.28319 6.28319" actuatorfrcrange="-54 54" armature="0.000038200"/>
                  <geom type="mesh" contype="0" conaffinity="0" group="1" density="0" rgba="0.7 0.7 0.7 1" mesh="wrist3"/>
                  <geom type="mesh" rgba="0.7 0.7 0.7 1" mesh="wrist3"/>
                  <body name="ee_link" pos="0 0.0819 0" quat="0.707107 0 0 0.707107">
                    <geom size="0.005 0.005 0.005" pos="-0.01 0 0" type="box"/>
                  </body>
                  <!--body name="tool0" pos="0 0.0819 0" quat="0.707107 -0.707107 0 0"/-->
                </body>
              </body>
            </body>
          </body>
        </body>
      </body>
      <body name="base" quat="0 0 0 -1"/>
    </body>
  </worldbody>
  <contact>
    <exclude body1="base_link" body2="shoulder_link"/>
  </contact>
  <actuator>
    <position name="j_shoulder_pan_joint" joint="shoulder_pan_joint" kp="0.01" dampratio="1" gear="101" ctrlrange="-317.300858013 317.300858013" forcerange="-30.000000000 30.000000000"/>
    <position name="j_shoulder_lift_joint" joint="shoulder_lift_joint" kp="0.01" dampratio="1" gear="101" ctrlrange="-317.300858013 317.300858013" forcerange="-30.000000000 30.000000000"/>
    <position name="j_elbow_joint" joint="elbow_joint" kp="0.01" dampratio="1" gear="101" ctrlrange="-317.300858013 317.300858013" forcerange="-30.000000000 30.000000000"/>
    <position name="j_wrist_1_joint" joint="wrist_1_joint" kp="0.01" dampratio="1" gear="101" ctrlrange="-317.300858013 317.300858013" forcerange="-30.000000000 30.000000000"/>
    <position name="j_wrist_2_joint" joint="wrist_2_joint" kp="0.01" dampratio="1" gear="101" ctrlrange="-317.300858013 317.300858013" forcerange="-30.000000000 30.000000000"/>
    <position name="j_wrist_3_joint" joint="wrist_3_joint" kp="0.01" dampratio="1" gear="101" ctrlrange="-317.300858013 317.300858013" forcerange="-30.000000000 30.000000000"/>
  </actuator>
  <sensor>
    <jointpos name="s_shoulder_pan_joint" joint="shoulder_pan_joint"/>
    <jointpos name="s_shoulder_lift_joint" joint="shoulder_lift_joint"/>
    <jointpos name="s_elbow_joint" joint="elbow_joint"/>
    <jointpos name="s_wrist_1_joint" joint="wrist_1_joint"/>
    <jointpos name="s_wrist_2_joint" joint="wrist_2_joint"/>
    <jointpos name="s_wrist_3_joint" joint="wrist_3_joint"/>
  </sensor>
</mujoco>
